Workbook

Sheet Data Aset
A1: TEMPLATE DATA ASET - INVENTARIS RUANGAN
A3: No | B3: Kode Aset | C3: Unit | D3: Lokasi/Ruangan | E3: Jenis Barang | F3: Nama Barang | G3: Bahan | H3: Ukuran | I3: Jumlah | J3: Tanggal Perolehan | K3: Tahun Perolehan | L3: Harga Satuan | M3: Total Harga | N3: Kode Akun Aset | O3: Umur Manfaat | P3: Akum. Penyusutan | Q3: Nilai Buku | R3: Kondisi | S3: Status | T3: Keterangan | U3: Sumber Data
A4: 1 | C4: TKIA 24 JATIKRAMAT | E4: Wastafell | F4: Wastafell | I4: 1 Unit | K4: 2018 | M4: 600000 | O4: 4 | P4: 600000 | Q4: 0 | S4: Aktif | U4: LIST ASSET YPIK 2025(1).xlsx | Inv. TKIA
A5: 2 | C5: TKIA 24 JATIKRAMAT | E5: Lemari 4 Pintu | F5: Lemari 4 Pintu | I5: 1 Unit | K5: 2018 | M5: 1500000 | O5: 4 | P5: 1500000 | Q5: 0 | S5: Aktif | U5: LIST ASSET YPIK 2025(1).xlsx | Inv. TKIA
A6: 3 | C6: TKIA 24 JATIKRAMAT | E6: Buffet Kayu | F6: Buffet Kayu | I6: 1 Unit | K6: 2018 | M6: 1500000 | O6: 4 | P6: 1500000 | Q6: 0 | S6: Aktif | U6: LIST ASSET YPIK 2025(1).xlsx | Inv. TKIA
A7: 4 | C7: TKIA 24 JATIKRAMAT | E7: Kontainer BDX | F7: Kontainer BDX | I7: 1 Unit | K7: 2018 | M7: 750000 | O7: 4 | P7: 750000 | Q7: 0 | S7: Aktif | U7: LIST ASSET YPIK 2025(1).xlsx | Inv. TKIA
A8: 5 | C8: TKIA 24 JATIKRAMAT | E8: Best Baby | F8: Best Baby | I8: 1 Unit | K8: 2018 | M8: 500000 | O8: 4 | P8: 500000 | Q8: 0 | S8: Aktif | U8: LIST ASSET YPIK 2025(1).xlsx | Inv. TKIA
A9: 6 | C9: TKIA 24 JATIKRAMAT | E9: Filling Kabinet 4 Rak | F9: Filling Kabinet 4 Rak | I9: 1 Unit | K9: 2018 | M9: 1750000 | O9: 4 | P9: 1750000 | Q9: 0 | S9: Aktif | U9: LIST ASSET YPIK 2025(1).xlsx | Inv. TKIA
A10: 7 | C10: TKIA 24 JATIKRAMAT | E10: Rak Buku | F10: Rak Buku | I10: 1 Unit | K10: 2018 | M10: 2000000 | O10: 4 | P10: 2000000 | Q10: 0 | S10: Aktif | U10: LIST ASSET YPIK 2025(1).xlsx | Inv. TKIA
A11: 8 | C11: TKIA 24 JATIKRAMAT | E11: Rak Buku 6 Tingkat | F11: Rak Buku 6 Tingkat | I11: 1 Unit | K11: 2018 | M11: 3500000 | O11: 4 | P11: 3500000 | Q11: 0 | S11: Aktif | U11: LIST ASSET YPIK 2025(1).xlsx | Inv. TKIA
A12: 9 | C12: TKIA 24 JATIKRAMAT | E12: Lemari 2 Pintu | F12: Lemari 2 Pintu | I12: 1 Unit | K12: 2018 | M12: 2000000 | O12: 4 | P12: 2000000 | Q12: 0 | S12: Aktif | U12: LIST ASSET YPIK 2025(1).xlsx | Inv. TKIA
A13: 10 | C13: TKIA 24 JATIKRAMAT | E13: Rak Buku Susun | F13: Rak Buku Susun | I13: 1 Unit | K13: 2018 | M13: 2000000 | O13: 4 | P13: 2000000 | Q13: 0 | S13: Aktif | U13: LIST ASSET YPIK 2025(1).xlsx | Inv. TKIA
A14: 11 | C14: TKIA 24 JATIKRAMAT | E14: Loker Guru | F14: Loker Guru | I14: 2 Unit | K14: 2018 | M14: 3000000 | O14: 4 | P14: 3000000 | Q14: 0 | S14: Aktif | U14: LIST ASSET YPIK 2025(1).xlsx | Inv. TKIA
A15: 12 | C15: TKIA 24 JATIKRAMAT | E15: TOA | F15: TOA | I15: 1 Unit | K15: 2018 | M15: 1500000 | O15: 4 | P15: 1500000 | Q15: 0 | S15: Aktif | U15: LIST ASSET YPIK 2025(1).xlsx | Inv. TKIA
... A103: 100 | C103: TKIA 24 JATIKRAMAT | E103: Pembelian Lemari Arsip Kantor Filling Kabinet 2 Pintu Besi Brankas Laci 2 untuk TKIA | F103: Pembelian Lemari Arsip Kantor Filling Kabinet 2 Pintu Besi Brankas Laci 2 untuk TKIA | I103: 1 Unit | K103: 2023 | M103: 2650000 | O103: 4 | P103: 1325000 | Q103: 1325000 | S103: Aktif | U103: LIST ASSET YPIK 2025(1).xlsx | Inv. TKIA
A104: 101 | C104: TKIA 24 JATIKRAMAT | E104: Pembelian Karpet Funil & Rumput Sintesis | F104: Pembelian Karpet Funil & Rumput Sintesis | K104: 2024 | M104: 6347300 | O104: 4 | P104: 2538920 | Q104: 3808380 | S104: Aktif | U104: LIST ASSET YPIK 2025(1).xlsx | Inv. TKIA
A105: 102 | C105: TKIA 24 JATIKRAMAT | E105: Pembelian Kursi Tunggu TKIA | F105: Pembelian Kursi Tunggu TKIA | K105: 2024 | M105: 2001500 | O105: 4 | P105: 767242 | Q105: 1234258 | S105: Aktif | U105: LIST ASSET YPIK 2025(1).xlsx | Inv. TKIA
A106: 103 | C106: TKIA 24 JATIKRAMAT | E106: Pembelian Display Termin III TKIA | F106: Pembelian Display Termin III TKIA | K106: 2024 | M106: 1250000 | O106: 4 | P106: 437500 | Q106: 812500 | S106: Aktif | U106: LIST ASSET YPIK 2025(1).xlsx | Inv. TKIA
A107: 104 | C107: TKIA 24 JATIKRAMAT | E107: Pembelian Kursi Lipat 10 Unit TKIA | F107: Pembelian Kursi Lipat 10 Unit TKIA | I107: 10 Unit | K107: 2024 | M107: 4113000 | O107: 4 | P107: 1233900 | Q107: 2879100 | S107: Aktif | U107: LIST ASSET YPIK 2025(1).xlsx | Inv. TKIA
A108: 105 | C108: TKIA 24 JATIKRAMAT | E108: Display Kelas TA 23/24 TKIA | F108: Display Kelas TA 23/24 TKIA | K108: 2024 | M108: 1250000 | O108: 4 | P108: 375000 | Q108: 875000 | S108: Aktif | U108: LIST ASSET YPIK 2025(1).xlsx | Inv. TKIA
A109: 106 | C109: TKIA 24 JATIKRAMAT | E109: Pembelian Kusen dan Rak Sepatu | F109: Pembelian Kusen dan Rak Sepatu | K109: 2024 | M109: 1700000 | O109: 4 | P109: 425000 | Q109: 1275000 | S109: Aktif | U109: LIST ASSET YPIK 2025(1).xlsx | Inv. TKIA
A110: 107 | C110: TKIA 24 JATIKRAMAT | E110: Pembelian 2 Unit Loker TKIA | F110: Pembelian 2 Unit Loker TKIA | I110: 2 Unit | K110: 2024 | M110: 9000000 | O110: 4 | P110: 1950000 | Q110: 7050000 | S110: Aktif | U110: LIST ASSET YPIK 2025(1).xlsx | Inv. TKIA
A111: 108 | C111: TKIA 24 JATIKRAMAT | E111: Display Kelas Term 3 TA 24/25 TKIA | F111: Display Kelas Term 3 TA 24/25 TKIA | K111: 2025 | M111: 1250000 | O111: 4 | P111: 229166.67 | Q111: 1020833.3 | S111: Aktif | U111: LIST ASSET YPIK 2025(1).xlsx | Inv. TKIA
A112: 109 | C112: TKIA 24 JATIKRAMAT | E112: Display Kelas Term IV TKIA | F112: Display Kelas Term IV TKIA | K112: 2025 | M112: 1250000 | O112: 4 | P112: 145833.33 | Q112: 1104166.7 | S112: Aktif | U112: LIST ASSET YPIK 2025(1).xlsx | Inv. TKIA
A113: 110 | C113: TKIA 24 JATIKRAMAT | E113: Pembelian 2 Unit Filling Kabinet Besi | F113: Pembelian 2 Unit Filling Kabinet Besi | K113: 2025 | M113: 4305720 | O113: 4 | P113: 430572 | Q113: 3875148 | S113: Aktif | U113: LIST ASSET YPIK 2025(1).xlsx | Inv. TKIA
A114: 111 | C114: TKIA 24 JATIKRAMAT | E114: Pembelian 5 Unit Karpet Besar untuk TKIA | F114: Pembelian 5 Unit Karpet Besar untuk TKIA | K114: 2025 | M114: 4028575 | O114: 4 | P114: 402857.5 | Q114: 3625717.5 | S114: Aktif | U114: LIST ASSET YPIK 2025(1).xlsx | Inv. TKIA
A115: 112 | C115: TKIA 24 JATIKRAMAT | E115: Display Kelas Term I TKIA TA 25/26 | F115: Display Kelas Term I TKIA TA 25/26 | K115: 2025 | M115: 1250000 | O115: 4 | P115: 83333.333 | Q115: 1166666.7 | S115: Aktif | U115: LIST ASSET YPIK 2025(1).xlsx | Inv. TKIA
A116: 113 | C116: SDIA 23 JATIKRAMAT | E116: Lemari Guru | F116: Lemari Guru | I116: 1 | K116: 2018 | M116: 2000000 | O116: 4 | P116: 2000000 | Q116: 0 | S116: Aktif | U116: LIST ASSET YPIK 2025(1).xlsx | Inv. SDIA
A117: 114 | C117: SDIA 23 JATIKRAMAT | E117: Meja Guru | F117: Meja Guru | I117: 1 | K117: 2018 | M117: 1500000 | O117: 4 | P117: 1500000 | Q117: 0 | S117: Aktif | U117: LIST ASSET YPIK 2025(1).xlsx | Inv. SDIA
A118: 115 | C118: SDIA 23 JATIKRAMAT | E118: Kursi Guru | F118: Kursi Guru | I118: 1 | K118: 2018 | M118: 300000 | O118: 4 | P118: 300000 | Q118: 0 | S118: Aktif | U118: LIST ASSET YPIK 2025(1).xlsx | Inv. SDIA
A119: 116 | C119: SDIA 23 JATIKRAMAT | E119: Loker Murid | F119: Loker Murid | I119: 2 | K119: 2018 | M119: 5000000 | O119: 4 | P119: 5000000 | Q119: 0 | S119: Aktif | U119: LIST ASSET YPIK 2025(1).xlsx | Inv. SDIA
A120: 117 | C120: SDIA 23 JATIKRAMAT | E120: Mading Besar | F120: Mading Besar | I120: 1 | K120: 2018 | M120: 1000000 | O120: 4 | P120: 1000000 | Q120: 0 | S120: Aktif | U120: LIST ASSET YPIK 2025(1).xlsx | Inv. SDIA
A121: 118 | C121: SDIA 23 JATIKRAMAT | E121: Whiteboard | F121: Whiteboard | I121: 1 | K121: 2018 | M121: 600000 | O121: 4 | P121: 600000 | Q121: 0 | S121: Aktif | U121: LIST ASSET YPIK 2025(1).xlsx | Inv. SDIA
A122: 119 | C122: SDIA 23 JATIKRAMAT | E122: Rak Sandal/Sepatu | F122: Rak Sandal/Sepatu | I122: 1 | K122: 2018 | M122: 2500000 | O122: 4 | P122: 2500000 | Q122: 0 | S122: Aktif | U122: LIST ASSET YPIK 2025(1).xlsx | Inv. SDIA
A123: 120 | C123: SDIA 23 JATIKRAMAT | E123: Kursi Murid 6 Abu | F123: Kursi Murid 6 Abu | I123: 29 | K123: 2018 | M123: 7250000 | O123: 4 | P123: 7250000 | Q123: 0 | S123: Aktif | U123: LIST ASSET YPIK 2025(1).xlsx | Inv. SDIA
A124: 121 | C124: SDIA 23 JATIKRAMAT | E124: Meja Murid 6 Abu | F124: Meja Murid 6 Abu | I124: 29 | K124: 2018 | M124: 4350000 | O124: 4 | P124: 4350000 | Q124: 0 | S124: Aktif | U124: LIST ASSET YPIK 2025(1).xlsx | Inv. SDIA
A125: 122 | C125: SDIA 23 JATIKRAMAT | E125: Lemari Guru | F125: Lemari Guru | I125: 1 | K125: 2018 | M125: 2000000 | O125: 4 | P125: 2000000 | Q125: 0 | S125: Aktif | U125: LIST ASSET YPIK 2025(1).xlsx | Inv. SDIA
A126: 123 | C126: SDIA 23 JATIKRAMAT | E126: Meja Guru | F126: Meja Guru | I126: 2 | K126: 2018 | M126: 1500000 | O126: 4 | P126: 1500000 | Q126: 0 | S126: Aktif | U126: LIST ASSET YPIK 2025(1).xlsx | Inv. SDIA
A127: 124 | C127: SDIA 23 JATIKRAMAT | E127: Kursi Guru | F127: Kursi Guru | I127: 2 | K127: 2018 | M127: 300000 | O127: 4 | P127: 300000 | Q127: 0 | S127: Aktif | U127: LIST ASSET YPIK 2025(1).xlsx | Inv. SDIA
... A295: 292 | C295: SDIA 23 JATIKRAMAT | E295: Kursi Murid | F295: Kursi Murid | I295: 27 | K295: 2018 | M295: 4050000 | O295: 4 | P295: 4050000 | Q295: 0 | S295: Aktif | U295: LIST ASSET YPIK 2025(1).xlsx | Inv. SDIA
...

Sheet Dashboard
A1: Dashboard Inventaris Ruangan
A3: Total Baris Data | B3: 891
A4: Total Harga Perolehan | B4: =SUM('Data Aset'!M4:M894)
A6: Kategori | B6: Jumlah
A7: Inventaris Ruangan | B7: 891

Sheet Penyusutan
A1: No | B1: Periode Penyusutan | C1: Kode Aset | D1: Nama Aset | E1: Kategori Aset | F1: Unit | G1: Tanggal/Tahun Perolehan | H1: Harga Perolehan | I1: Umur Manfaat | J1: Nilai Residu | K1: Metode Penyusutan | L1: Beban Penyusutan Bulanan | M1: Beban Penyusutan Tahunan | N1: Akumulasi Penyusutan | O1: Nilai Buku | P1: Status Penyusutan | Q1: Keterangan
A2: 1 | B2: Desember 2025 | C2: ='Data Aset'!B4 | D2: ='Data Aset'!F4 | E2: Inventaris Ruangan | F2: ='Data Aset'!C4 | G2: ='Data Aset'!J4 | H2: ='Data Aset'!M4 | I2: ='Data Aset'!O4 | J2: 0 | K2: Garis Lurus | L2: =IFERROR(M2/12,"") | M2: =IFERROR((H2-J2)/I2,"") | N2: =IFERROR(M2,"") | O2: =IFERROR(H2-N2,"") | P2: Belum dihitung
A3: 2 | B3: Desember 2025 | C3: ='Data Aset'!B5 | D3: ='Data Aset'!F5 | E3: Inventaris Ruangan | F3: ='Data Aset'!C5 | G3: ='Data Aset'!J5 | H3: ='Data Aset'!M5 | I3: ='Data Aset'!O5 | J3: 0 | K3: Garis Lurus | L3: =IFERROR(M3/12,"") | M3: =IFERROR((H3-J3)/I3,"") | N3: =IFERROR(M3,"") | O3: =IFERROR(H3-N3,"") | P3: Belum dihitung
A4: 3 | B4: Desember 2025 | C4: ='Data Aset'!B6 | D4: ='Data Aset'!F6 | E4: Inventaris Ruangan | F4: ='Data Aset'!C6 | G4: ='Data Aset'!J6 | H4: ='Data Aset'!M6 | I4: ='Data Aset'!O6 | J4: 0 | K4: Garis Lurus | L4: =IFERROR(M4/12,"") | M4: =IFERROR((H4-J4)/I4,"") | N4: =IFERROR(M4,"") | O4: =IFERROR(H4-N4,"") | P4: Belum dihitung
A5: 4 | B5: Desember 2025 | C5: ='Data Aset'!B7 | D5: ='Data Aset'!F7 | E5: Inventaris Ruangan | F5: ='Data Aset'!C7 | G5: ='Data Aset'!J7 | H5: ='Data Aset'!M7 | I5: ='Data Aset'!O7 | J5: 0 | K5: Garis Lurus | L5: =IFERROR(M5/12,"") | M5: =IFERROR((H5-J5)/I5,"") | N5: =IFERROR(M5,"") | O5: =IFERROR(H5-N5,"") | P5: Belum dihitung
A6: 5 | B6: Desember 2025 | C6: ='Data Aset'!B8 | D6: ='Data Aset'!F8 | E6: Inventaris Ruangan | F6: ='Data Aset'!C8 | G6: ='Data Aset'!J8 | H6: ='Data Aset'!M8 | I6: ='Data Aset'!O8 | J6: 0 | K6: Garis Lurus | L6: =IFERROR(M6/12,"") | M6: =IFERROR((H6-J6)/I6,"") | N6: =IFERROR(M6,"") | O6: =IFERROR(H6-N6,"") | P6: Belum dihitung
A7: 6 | B7: Desember 2025 | C7: ='Data Aset'!B9 | D7: ='Data Aset'!F9 | E7: Inventaris Ruangan | F7: ='Data Aset'!C9 | G7: ='Data Aset'!J9 | H7: ='Data Aset'!M9 | I7: ='Data Aset'!O9 | J7: 0 | K7: Garis Lurus | L7: =IFERROR(M7/12,"") | M7: =IFERROR((H7-J7)/I7,"") | N7: =IFERROR(M7,"") | O7: =IFERROR(H7-N7,"") | P7: Belum dihitung
A8: 7 | B8: Desember 2025 | C8: ='Data Aset'!B10 | D8: ='Data Aset'!F10 | E8: Inventaris Ruangan | F8: ='Data Aset'!C10 | G8: ='Data Aset'!J10 | H8: ='Data Aset'!M10 | I8: ='Data Aset'!O10 | J8: 0 | K8: Garis Lurus | L8: =IFERROR(M8/12,"") | M8: =IFERROR((H8-J8)/I8,"") | N8: =IFERROR(M8,"") | O8: =IFERROR(H8-N8,"") | P8: Belum dihitung
A9: 8 | B9: Desember 2025 | C9: ='Data Aset'!B11 | D9: ='Data Aset'!F11 | E9: Inventaris Ruangan | F9: ='Data Aset'!C11 | G9: ='Data Aset'!J11 | H9: ='Data Aset'!M11 | I9: ='Data Aset'!O11 | J9: 0 | K9: Garis Lurus | L9: =IFERROR(M9/12,"") | M9: =IFERROR((H9-J9)/I9,"") | N9: =IFERROR(M9,"") | O9: =IFERROR(H9-N9,"") | P9: Belum dihitung
A10: 9 | B10: Desember 2025 | C10: ='Data Aset'!B12 | D10: ='Data Aset'!F12 | E10: Inventaris Ruangan | F10: ='Data Aset'!C12 | G10: ='Data Aset'!J12 | H10: ='Data Aset'!M12 | I10: ='Data Aset'!O12 | J10: 0 | K10: Garis Lurus | L10: =IFERROR(M10/12,"") | M10: =IFERROR((H10-J10)/I10,"") | N10: =IFERROR(M10,"") | O10: =IFERROR(H10-N10,"") | P10: Belum dihitung
A11: 10 | B11: Desember 2025 | C11: ='Data Aset'!B13 | D11: ='Data Aset'!F13 | E11: Inventaris Ruangan | F11: ='Data Aset'!C13 | G11: ='Data Aset'!J13 | H11: ='Data Aset'!M13 | I11: ='Data Aset'!O13 | J11: 0 | K11: Garis Lurus | L11: =IFERROR(M11/12,"") | M11: =IFERROR((H11-J11)/I11,"") | N11: =IFERROR(M11,"") | O11: =IFERROR(H11-N11,"") | P11: Belum dihitung
A12: 11 | B12: Desember 2025 | C12: ='Data Aset'!B14 | D12: ='Data Aset'!F14 | E12: Inventaris Ruangan | F12: ='Data Aset'!C14 | G12: ='Data Aset'!J14 | H12: ='Data Aset'!M14 | I12: ='Data Aset'!O14 | J12: 0 | K12: Garis Lurus | L12: =IFERROR(M12/12,"") | M12: =IFERROR((H12-J12)/I12,"") | N12: =IFERROR(M12,"") | O12: =IFERROR(H12-N12,"") | P12: Belum dihitung
A13: 12 | B13: Desember 2025 | C13: ='Data Aset'!B15 | D13: ='Data Aset'!F15 | E13: Inventaris Ruangan | F13: ='Data Aset'!C15 | G13: ='Data Aset'!J15 | H13: ='Data Aset'!M15 | I13: ='Data Aset'!O15 | J13: 0 | K13: Garis Lurus | L13: =IFERROR(M13/12,"") | M13: =IFERROR((H13-J13)/I13,"") | N13: =IFERROR(M13,"") | O13: =IFERROR(H13-N13,"") | P13: Belum dihitung
... A892: 891 | B892: Desember 2025 | C892: ='Data Aset'!B894 | D892: ='Data Aset'!F894 | E892: Inventaris Ruangan | F892: ='Data Aset'!C894 | G892: ='Data Aset'!J894 | H892: ='Data Aset'!M894 | I892: ='Data Aset'!O894 | J892: 0 | K892: Garis Lurus | L892: =IFERROR(M892/12,"") | M892: =IFERROR((H892-J892)/I892,"") | N892: =IFERROR(M892,"") | O892: =IFERROR(H892-N892,"") | P892: Belum dihitung

Sheet Jurnal Penyusutan
A1: No Jurnal | B1: Tanggal Jurnal | C1: Periode | D1: Kode Aset | E1: Nama Aset | F1: Kategori Aset | G1: Kode Akun Debit | H1: Nama Akun Debit | I1: Debit | J1: Kode Akun Kredit | K1: Nama Akun Kredit | L1: Kredit | M1: Keterangan
A2: =IF(Penyusutan!D2="","","JRN-"&TEXT(ROW()-1,"0000")) | B2: 46022 | C2: =Penyusutan!B2 | D2: =Penyusutan!C2 | E2: =Penyusutan!D2 | F2: Inventaris Ruangan | H2: Beban Penyusutan Inventaris Ruangan | I2: =Penyusutan!M2 | K2: Akumulasi Penyusutan Inventaris Ruangan | L2: =Penyusutan!M2 | M2: =IF(E2="","","Penyusutan "&E2&" periode "&C2)
A3: =IF(Penyusutan!D3="","","JRN-"&TEXT(ROW()-1,"0000")) | B3: 46022 | C3: =Penyusutan!B3 | D3: =Penyusutan!C3 | E3: =Penyusutan!D3 | F3: Inventaris Ruangan | H3: Beban Penyusutan Inventaris Ruangan | I3: =Penyusutan!M3 | K3: Akumulasi Penyusutan Inventaris Ruangan | L3: =Penyusutan!M3 | M3: =IF(E3="","","Penyusutan "&E3&" periode "&C3)
A4: =IF(Penyusutan!D4="","","JRN-"&TEXT(ROW()-1,"0000")) | B4: 46022 | C4: =Penyusutan!B4 | D4: =Penyusutan!C4 | E4: =Penyusutan!D4 | F4: Inventaris Ruangan | H4: Beban Penyusutan Inventaris Ruangan | I4: =Penyusutan!M4 | K4: Akumulasi Penyusutan Inventaris Ruangan | L4: =Penyusutan!M4 | M4: =IF(E4="","","Penyusutan "&E4&" periode "&C4)
A5: =IF(Penyusutan!D5="","","JRN-"&TEXT(ROW()-1,"0000")) | B5: 46022 | C5: =Penyusutan!B5 | D5: =Penyusutan!C5 | E5: =Penyusutan!D5 | F5: Inventaris Ruangan | H5: Beban Penyusutan Inventaris Ruangan | I5: =Penyusutan!M5 | K5: Akumulasi Penyusutan Inventaris Ruangan | L5: =Penyusutan!M5 | M5: =IF(E5="","","Penyusutan "&E5&" periode "&C5)
A6: =IF(Penyusutan!D6="","","JRN-"&TEXT(ROW()-1,"0000")) | B6: 46022 | C6: =Penyusutan!B6 | D6: =Penyusutan!C6 | E6: =Penyusutan!D6 | F6: Inventaris Ruangan | H6: Beban Penyusutan Inventaris Ruangan | I6: =Penyusutan!M6 | K6: Akumulasi Penyusutan Inventaris Ruangan | L6: =Penyusutan!M6 | M6: =IF(E6="","","Penyusutan "&E6&" periode "&C6)
A7: =IF(Penyusutan!D7="","","JRN-"&TEXT(ROW()-1,"0000")) | B7: 46022 | C7: =Penyusutan!B7 | D7: =Penyusutan!C7 | E7: =Penyusutan!D7 | F7: Inventaris Ruangan | H7: Beban Penyusutan Inventaris Ruangan | I7: =Penyusutan!M7 | K7: Akumulasi Penyusutan Inventaris Ruangan | L7: =Penyusutan!M7 | M7: =IF(E7="","","Penyusutan "&E7&" periode "&C7)
A8: =IF(Penyusutan!D8="","","JRN-"&TEXT(ROW()-1,"0000")) | B8: 46022 | C8: =Penyusutan!B8 | D8: =Penyusutan!C8 | E8: =Penyusutan!D8 | F8: Inventaris Ruangan | H8: Beban Penyusutan Inventaris Ruangan | I8: =Penyusutan!M8 | K8: Akumulasi Penyusutan Inventaris Ruangan | L8: =Penyusutan!M8 | M8: =IF(E8="","","Penyusutan "&E8&" periode "&C8)
A9: =IF(Penyusutan!D9="","","JRN-"&TEXT(ROW()-1,"0000")) | B9: 46022 | C9: =Penyusutan!B9 | D9: =Penyusutan!C9 | E9: =Penyusutan!D9 | F9: Inventaris Ruangan | H9: Beban Penyusutan Inventaris Ruangan | I9: =Penyusutan!M9 | K9: Akumulasi Penyusutan Inventaris Ruangan | L9: =Penyusutan!M9 | M9: =IF(E9="","","Penyusutan "&E9&" periode "&C9)
A10: =IF(Penyusutan!D10="","","JRN-"&TEXT(ROW()-1,"0000")) | B10: 46022 | C10: =Penyusutan!B10 | D10: =Penyusutan!C10 | E10: =Penyusutan!D10 | F10: Inventaris Ruangan | H10: Beban Penyusutan Inventaris Ruangan | I10: =Penyusutan!M10 | K10: Akumulasi Penyusutan Inventaris Ruangan | L10: =Penyusutan!M10 | M10: =IF(E10="","","Penyusutan "&E10&" periode "&C10)
A11: =IF(Penyusutan!D11="","","JRN-"&TEXT(ROW()-1,"0000")) | B11: 46022 | C11: =Penyusutan!B11 | D11: =Penyusutan!C11 | E11: =Penyusutan!D11 | F11: Inventaris Ruangan | H11: Beban Penyusutan Inventaris Ruangan | I11: =Penyusutan!M11 | K11: Akumulasi Penyusutan Inventaris Ruangan | L11: =Penyusutan!M11 | M11: =IF(E11="","","Penyusutan "&E11&" periode "&C11)
A12: =IF(Penyusutan!D12="","","JRN-"&TEXT(ROW()-1,"0000")) | B12: 46022 | C12: =Penyusutan!B12 | D12: =Penyusutan!C12 | E12: =Penyusutan!D12 | F12: Inventaris Ruangan | H12: Beban Penyusutan Inventaris Ruangan | I12: =Penyusutan!M12 | K12: Akumulasi Penyusutan Inventaris Ruangan | L12: =Penyusutan!M12 | M12: =IF(E12="","","Penyusutan "&E12&" periode "&C12)
A13: =IF(Penyusutan!D13="","","JRN-"&TEXT(ROW()-1,"0000")) | B13: 46022 | C13: =Penyusutan!B13 | D13: =Penyusutan!C13 | E13: =Penyusutan!D13 | F13: Inventaris Ruangan | H13: Beban Penyusutan Inventaris Ruangan | I13: =Penyusutan!M13 | K13: Akumulasi Penyusutan Inventaris Ruangan | L13: =Penyusutan!M13 | M13: =IF(E13="","","Penyusutan "&E13&" periode "&C13)
... A892: =IF(Penyusutan!D892="","","JRN-"&TEXT(ROW()-1,"0000")) | B892: 46022 | C892: =Penyusutan!B892 | D892: =Penyusutan!C892 | E892: =Penyusutan!D892 | F892: Inventaris Ruangan | H892: Beban Penyusutan Inventaris Ruangan | I892: =Penyusutan!M892 | K892: Akumulasi Penyusutan Inventaris Ruangan | L892: =Penyusutan!M892 | M892: =IF(E892="","","Penyusutan "&E892&" periode "&C892)

Sheet Referensi
A1: Jenis Referensi | B1: Nilai
A2: Kondisi | B2: Baik
A3: Kondisi | B3: Kurang Baik
A4: Kondisi | B4: Rusak Ringan
A5: Kondisi | B5: Rusak Berat
A6: Kondisi | B6: Dalam Perbaikan
A7: Kondisi | B7: Hilang
A8: Status | B8: Aktif
A9: Status | B9: Tidak Aktif
A10: Status | B10: Dipindahkan
A11: Status | B11: Dihapuskan
A12: Status | B12: Dijual
... A14: Metode Penyusutan | B14: Saldo Menurun
