Workbook

Sheet Data Aset
A1: TEMPLATE DATA ASET - ELEKTRONIK
A3: No | B3: Kode Aset | C3: Unit | D3: Lokasi | E3: Jenis Elektronik | F3: Nama Aset | G3: Merk | H3: Model/Tipe | I3: Spesifikasi | J3: Nomor Seri | K3: Tanggal Perolehan | L3: Tahun Perolehan | M3: Harga Perolehan | N3: Kode Akun Aset | O3: Umur Manfaat | P3: Akum. Penyusutan | Q3: Nilai Buku | R3: Kondisi | S3: Status | T3: PIC/Pengguna | U3: Keterangan | V3: Sumber Data
A4: 1 | C4: TKIA 24 JATIKRAMAT | E4: Infocus | F4: Infocus | I4: Jumlah: 1 Unit | L4: 2018 | M4: 3000000 | O4: 4 | P4: 3000000 | Q4: 0 | S4: Aktif | V4: LIST ASSET YPIK 2025(1).xlsx | Inv. TKIA
A5: 2 | C5: TKIA 24 JATIKRAMAT | E5: Sound System | F5: Sound System | I5: Jumlah: 1 Unit | L5: 2018 | M5: 500000 | O5: 4 | P5: 500000 | Q5: 0 | S5: Aktif | V5: LIST ASSET YPIK 2025(1).xlsx | Inv. TKIA
A6: 3 | C6: TKIA 24 JATIKRAMAT | E6: CCTV | F6: CCTV | I6: Jumlah: 1 Unit | L6: 2018 | M6: 1250000 | O6: 4 | P6: 1250000 | Q6: 0 | S6: Aktif | V6: LIST ASSET YPIK 2025(1).xlsx | Inv. TKIA
A7: 4 | C7: TKIA 24 JATIKRAMAT | E7: Dispenser | F7: Dispenser | I7: Jumlah: 1 Unit | L7: 2018 | M7: 200000 | O7: 4 | P7: 200000 | Q7: 0 | S7: Aktif | V7: LIST ASSET YPIK 2025(1).xlsx | Inv. TKIA
A8: 5 | C8: TKIA 24 JATIKRAMAT | E8: Kipas Angin | F8: Kipas Angin | I8: Jumlah: 1 Unit | L8: 2018 | M8: 500000 | O8: 4 | P8: 500000 | Q8: 0 | S8: Aktif | V8: LIST ASSET YPIK 2025(1).xlsx | Inv. TKIA
A9: 6 | C9: TKIA 24 JATIKRAMAT | E9: CCTV Central | F9: CCTV Central | I9: Jumlah: 1 Unit | L9: 2018 | M9: 3000000 | O9: 4 | P9: 3000000 | Q9: 0 | S9: Aktif | V9: LIST ASSET YPIK 2025(1).xlsx | Inv. TKIA
A10: 7 | C10: TKIA 24 JATIKRAMAT | E10: Kulkas 2 Pintu | F10: Kulkas 2 Pintu | I10: Jumlah: 1 Unit | L10: 2018 | M10: 2000000 | O10: 4 | P10: 2000000 | Q10: 0 | S10: Aktif | V10: LIST ASSET YPIK 2025(1).xlsx | Inv. TKIA
A11: 8 | C11: TKIA 24 JATIKRAMAT | E11: Kipas Angin | F11: Kipas Angin | I11: Jumlah: 1 Unit | L11: 2018 | M11: 500000 | O11: 4 | P11: 500000 | Q11: 0 | S11: Aktif | V11: LIST ASSET YPIK 2025(1).xlsx | Inv. TKIA
A12: 9 | C12: TKIA 24 JATIKRAMAT | E12: Mic Wireless | F12: Mic Wireless | I12: Jumlah: 1 Unit | L12: 2018 | M12: 1000000 | O12: 4 | P12: 1000000 | Q12: 0 | S12: Aktif | V12: LIST ASSET YPIK 2025(1).xlsx | Inv. TKIA
A13: 10 | C13: TKIA 24 JATIKRAMAT | E13: CCTV - Sensor | F13: CCTV - Sensor | I13: Jumlah: 1 Unit | L13: 2018 | M13: 1500000 | O13: 4 | P13: 1500000 | Q13: 0 | S13: Aktif | V13: LIST ASSET YPIK 2025(1).xlsx | Inv. TKIA
A14: 11 | C14: TKIA 24 JATIKRAMAT | E14: Infocus | F14: Infocus | I14: Jumlah: 1 Unit | L14: 2018 | M14: 3000000 | O14: 4 | P14: 3000000 | Q14: 0 | S14: Aktif | V14: LIST ASSET YPIK 2025(1).xlsx | Inv. TKIA
A15: 12 | C15: TKIA 24 JATIKRAMAT | E15: Layar Infocus | F15: Layar Infocus | I15: Jumlah: 1 Unit | L15: 2018 | M15: 1500000 | O15: 4 | P15: 1500000 | Q15: 0 | S15: Aktif | V15: LIST ASSET YPIK 2025(1).xlsx | Inv. TKIA
... A23: 20 | C23: TKIA 24 JATIKRAMAT | E23: Kipas Angin | F23: Kipas Angin | I23: Jumlah: 1 Unit | L23: 2018 | M23: 300000 | O23: 4 | P23: 300000 | Q23: 0 | S23: Aktif | V23: LIST ASSET YPIK 2025(1).xlsx | Inv. TKIA
A24: 21 | C24: TKIA 24 JATIKRAMAT | E24: Maintenance CCTV TKIA | F24: Maintenance CCTV TKIA | L24: 2023 | M24: 370000 | O24: 4 | P24: 185000 | Q24: 185000 | S24: Aktif | V24: LIST ASSET YPIK 2025(1).xlsx | Inv. TKIA
A25: 22 | C25: TKIA 24 JATIKRAMAT | E25: Pembelian Lampu Panasonic Untuk TKIA (Mitra 10) | F25: Pembelian Lampu Panasonic Untuk TKIA (Mitra 10) | L25: 2023 | M25: 1359500 | O25: 4 | P25: 634433 | Q25: 725067 | S25: Aktif | V25: LIST ASSET YPIK 2025(1).xlsx | Inv. TKIA
A26: 23 | C26: TKIA 24 JATIKRAMAT | E26: Pembelian Kipas Angin/Blower Lantai 1 TA 2023/2024 TKIA | F26: Pembelian Kipas Angin/Blower Lantai 1 TA 2023/2024 TKIA | I26: Jumlah: 1 Unit | L26: 2023 | M26: 1000000 | O26: 4 | P26: 433333 | Q26: 566667 | S26: Aktif | V26: LIST ASSET YPIK 2025(1).xlsx | Inv. TKIA
A27: 24 | C27: TKIA 24 JATIKRAMAT | E27: Penambahan CCTV TKIA | F27: Penambahan CCTV TKIA | I27: Jumlah: 5 U nit | L27: 2023 | M27: 9690000 | O27: 4 | P27: 4037500 | Q27: 5652500 | S27: Aktif | V27: LIST ASSET YPIK 2025(1).xlsx | Inv. TKIA
A28: 25 | C28: SDIA 23 JATIKRAMAT | E28: Kulkas | F28: Kulkas | I28: Jumlah: 1 | L28: 2018 | M28: 1500000 | O28: 4 | P28: 1500000 | Q28: 0 | S28: Aktif | V28: LIST ASSET YPIK 2025(1).xlsx | Inv. SDIA
A29: 26 | C29: SDIA 23 JATIKRAMAT | E29: CCTV SDIA 23 | F29: CCTV SDIA 23 | I29: Jumlah: 14 Unit | L29: 2019 | M29: 28000000 | O29: 4 | P29: 28000000 | Q29: 0 | S29: Aktif | V29: LIST ASSET YPIK 2025(1).xlsx | Inv. SDIA
A30: 27 | C30: SDIA 23 JATIKRAMAT | E30: CCTV SDIA | F30: CCTV SDIA | L30: 2023 | M30: 2500000 | O30: 4 | P30: 1250000 | Q30: 1250000 | S30: Aktif | V30: LIST ASSET YPIK 2025(1).xlsx | Inv. SDIA
A31: 28 | C31: SDIA 23 JATIKRAMAT | E31: Pembelian Mic Wireless (1 Pasang) | F31: Pembelian Mic Wireless (1 Pasang) | I31: Jumlah: 1 Unit | L31: 2023 | M31: 664000 | O31: 4 | P31: 376267 | Q31: 287733 | S31: Aktif | V31: LIST ASSET YPIK 2025(1).xlsx | Inv. SDIA
A32: 29 | C32: SDIA 23 JATIKRAMAT | E32: Pembelian Bracket TV Standing 2 Unit untuk SDIA | F32: Pembelian Bracket TV Standing 2 Unit untuk SDIA | I32: Jumlah: 2 Unit | L32: 2023 | M32: 1700000 | O32: 4 | P32: 850000 | Q32: 850000 | S32: Aktif | V32: LIST ASSET YPIK 2025(1).xlsx | Inv. SDIA
A33: 30 | C33: SDIA 23 JATIKRAMAT | E33: DP Pembelian Sound System SDIA | F33: DP Pembelian Sound System SDIA | I33: Jumlah: 1 Set | L33: 2023 | M33: 30000000 | O33: 4 | P33: 14500000 | Q33: 15500000 | S33: Aktif | V33: LIST ASSET YPIK 2025(1).xlsx | Inv. SDIA
A34: 31 | C34: SDIA 23 JATIKRAMAT | E34: Pelunasan Pembelian Sound System/Speaker untuk SDIA | F34: Pelunasan Pembelian Sound System/Speaker untuk SDIA | I34: Jumlah: 1 Set | L34: 2023 | M34: 26000000 | O34: 4 | P34: 12566667 | Q34: 13433333 | S34: Aktif | V34: LIST ASSET YPIK 2025(1).xlsx | Inv. SDIA
A35: 32 | C35: SDIA 23 JATIKRAMAT | E35: Pembelian Lampu Panasonic di Mitra 10 Tgl 23 Sept 2023 | F35: Pembelian Lampu Panasonic di Mitra 10 Tgl 23 Sept 2023 | L35: 2023 | M35: 974700 | O35: 4 | P35: 454860 | Q35: 519840 | S35: Aktif | V35: LIST ASSET YPIK 2025(1).xlsx | Inv. SDIA
A36: 33 | C36: SDIA 23 JATIKRAMAT | E36: Pembelian Lampu Philips (Mitra 10) Tgl 24 Okt 2023 | F36: Pembelian Lampu Philips (Mitra 10) Tgl 24 Okt 2023 | L36: 2023 | M36: 3828200 | O36: 4 | P36: 1722690 | Q36: 2105510 | S36: Aktif | V36: LIST ASSET YPIK 2025(1).xlsx | Inv. SDIA
A37: 34 | C37: SDIA 23 JATIKRAMAT | E37: Pembelian Lampu dan Operasional Tgl 31 Okt 2023 | F37: Pembelian Lampu dan Operasional Tgl 31 Okt 2023 | L37: 2023 | M37: 905500 | O37: 4 | P37: 392383 | Q37: 513117 | S37: Aktif | V37: LIST ASSET YPIK 2025(1).xlsx | Inv. SDIA
A38: 35 | C38: SDIA 23 JATIKRAMAT | E38: Pembelian Dispenser & Jam Dinding SD | F38: Pembelian Dispenser & Jam Dinding SD | L38: 2024 | M38: 355400 | O38: 4 | P38: 112543 | Q38: 242857 | S38: Aktif | V38: LIST ASSET YPIK 2025(1).xlsx | Inv. SDIA
A39: 36 | C39: SDIA 23 JATIKRAMAT | E39: Pembelian Kipas Angin Satpam SDIA | F39: Pembelian Kipas Angin Satpam SDIA | L39: 2024 | M39: 350000 | O39: 4 | P39: 99167 | Q39: 250833 | S39: Aktif | V39: LIST ASSET YPIK 2025(1).xlsx | Inv. SDIA
A40: 37 | C40: SDIA 23 JATIKRAMAT | E40: Pembelian Microphone SDIA | F40: Pembelian Microphone SDIA | L40: 2024 | M40: 458300 | O40: 4 | P40: 122213 | Q40: 336087 | S40: Aktif | V40: LIST ASSET YPIK 2025(1).xlsx | Inv. SDIA
A41: 38 | C41: SDIA 23 JATIKRAMAT | E41: Pembelian Mic & Kabel SDIA | F41: Pembelian Mic & Kabel SDIA | L41: 2024 | M41: 218000 | O41: 4 | P41: 58133 | Q41: 159867 | S41: Aktif | V41: LIST ASSET YPIK 2025(1).xlsx | Inv. SDIA
A42: 39 | C42: SDIA 23 JATIKRAMAT | E42: Pembelian TV Plasma Aqua 58 Inch 2 Unit | F42: Pembelian TV Plasma Aqua 58 Inch 2 Unit | L42: 2025 | M42: 14789500 | O42: 4 | P42: 1725441.7 | Q42: 13064058 | S42: Aktif | V42: LIST ASSET YPIK 2025(1).xlsx | Inv. SDIA
A43: 40 | C43: SDIA 23 JATIKRAMAT | E43: Pembelian 5 Unit TV Plasma Aqua 58 Inch untuk SDIA & TKIA | F43: Pembelian 5 Unit TV Plasma Aqua 58 Inch untuk SDIA & TKIA | L43: 2025 | M43: 31495000 | O43: 4 | P43: 3149500 | Q43: 28345500 | S43: Aktif | V43: LIST ASSET YPIK 2025(1).xlsx | Inv. SDIA
A44: 41 | C44: SDIA 23 JATIKRAMAT | E44: Pembelian 5 Unit Bracket Standing TV Plasma | F44: Pembelian 5 Unit Bracket Standing TV Plasma | L44: 2025 | M44: 6262500 | O44: 4 | P44: 626250 | Q44: 5636250 | S44: Aktif | V44: LIST ASSET YPIK 2025(1).xlsx | Inv. SDIA
A45: 42 | C45: SDIA 23 JATIKRAMAT | E45: Pembelian 3 Unit Dispenser untuk Kelas Baru SDIA | F45: Pembelian 3 Unit Dispenser untuk Kelas Baru SDIA | L45: 2025 | M45: 674200 | O45: 4 | P45: 67420 | Q45: 606780 | S45: Aktif | V45: LIST ASSET YPIK 2025(1).xlsx | Inv. SDIA
A46: 43 | C46: YPIK PAM JAYA | E46: Proyektor & Sreeen Shoot | F46: Proyektor & Sreeen Shoot | I46: Jumlah: 1 Unit | L46: 2018 | M46: 4000000 | O46: 4 | P46: 4000000 | Q46: 0 | S46: Aktif | V46: LIST ASSET YPIK 2025(1).xlsx | Inv. YPIK
A47: 44 | C47: YPIK PAM JAYA | E47: CCTV - 4 Camera, Recorder dll | F47: CCTV - 4 Camera, Recorder dll | I47: Jumlah: 1 Set | L47: 2018 | M47: 18036000 | O47: 4 | P47: 18036000 | Q47: 0 | S47: Aktif | V47: LIST ASSET YPIK 2025(1).xlsx | Inv. YPIK
A48: 45 | C48: YPIK PAM JAYA | E48: Pembelian Lampu Panasonic Podcast | F48: Pembelian Lampu Panasonic Podcast | L48: 2024 | M48: 1060000 | O48: 4 | P48: 388667 | Q48: 671333 | S48: Aktif | V48: LIST ASSET YPIK 2025(1).xlsx | Inv. YPIK
...

Sheet Dashboard
A1: Dashboard Elektronik
A3: Total Baris Data | B3: 103
A4: Total Harga Perolehan | B4: =SUM('Data Aset'!M4:M106)
A6: Kategori | B6: Jumlah
A7: Elektronik | B7: 103

Sheet Penyusutan
A1: No | B1: Periode Penyusutan | C1: Kode Aset | D1: Nama Aset | E1: Kategori Aset | F1: Unit | G1: Tanggal/Tahun Perolehan | H1: Harga Perolehan | I1: Umur Manfaat | J1: Nilai Residu | K1: Metode Penyusutan | L1: Beban Penyusutan Bulanan | M1: Beban Penyusutan Tahunan | N1: Akumulasi Penyusutan | O1: Nilai Buku | P1: Status Penyusutan | Q1: Keterangan
A2: 1 | B2: Desember 2025 | C2: ='Data Aset'!B4 | D2: ='Data Aset'!F4 | E2: Elektronik | F2: ='Data Aset'!C4 | G2: ='Data Aset'!K4 | H2: ='Data Aset'!M4 | I2: ='Data Aset'!O4 | J2: 0 | K2: Garis Lurus | L2: =IFERROR(M2/12,"") | M2: =IFERROR((H2-J2)/I2,"") | N2: =IFERROR(M2,"") | O2: =IFERROR(H2-N2,"") | P2: Belum dihitung
A3: 2 | B3: Desember 2025 | C3: ='Data Aset'!B5 | D3: ='Data Aset'!F5 | E3: Elektronik | F3: ='Data Aset'!C5 | G3: ='Data Aset'!K5 | H3: ='Data Aset'!M5 | I3: ='Data Aset'!O5 | J3: 0 | K3: Garis Lurus | L3: =IFERROR(M3/12,"") | M3: =IFERROR((H3-J3)/I3,"") | N3: =IFERROR(M3,"") | O3: =IFERROR(H3-N3,"") | P3: Belum dihitung
A4: 3 | B4: Desember 2025 | C4: ='Data Aset'!B6 | D4: ='Data Aset'!F6 | E4: Elektronik | F4: ='Data Aset'!C6 | G4: ='Data Aset'!K6 | H4: ='Data Aset'!M6 | I4: ='Data Aset'!O6 | J4: 0 | K4: Garis Lurus | L4: =IFERROR(M4/12,"") | M4: =IFERROR((H4-J4)/I4,"") | N4: =IFERROR(M4,"") | O4: =IFERROR(H4-N4,"") | P4: Belum dihitung
A5: 4 | B5: Desember 2025 | C5: ='Data Aset'!B7 | D5: ='Data Aset'!F7 | E5: Elektronik | F5: ='Data Aset'!C7 | G5: ='Data Aset'!K7 | H5: ='Data Aset'!M7 | I5: ='Data Aset'!O7 | J5: 0 | K5: Garis Lurus | L5: =IFERROR(M5/12,"") | M5: =IFERROR((H5-J5)/I5,"") | N5: =IFERROR(M5,"") | O5: =IFERROR(H5-N5,"") | P5: Belum dihitung
A6: 5 | B6: Desember 2025 | C6: ='Data Aset'!B8 | D6: ='Data Aset'!F8 | E6: Elektronik | F6: ='Data Aset'!C8 | G6: ='Data Aset'!K8 | H6: ='Data Aset'!M8 | I6: ='Data Aset'!O8 | J6: 0 | K6: Garis Lurus | L6: =IFERROR(M6/12,"") | M6: =IFERROR((H6-J6)/I6,"") | N6: =IFERROR(M6,"") | O6: =IFERROR(H6-N6,"") | P6: Belum dihitung
A7: 6 | B7: Desember 2025 | C7: ='Data Aset'!B9 | D7: ='Data Aset'!F9 | E7: Elektronik | F7: ='Data Aset'!C9 | G7: ='Data Aset'!K9 | H7: ='Data Aset'!M9 | I7: ='Data Aset'!O9 | J7: 0 | K7: Garis Lurus | L7: =IFERROR(M7/12,"") | M7: =IFERROR((H7-J7)/I7,"") | N7: =IFERROR(M7,"") | O7: =IFERROR(H7-N7,"") | P7: Belum dihitung
A8: 7 | B8: Desember 2025 | C8: ='Data Aset'!B10 | D8: ='Data Aset'!F10 | E8: Elektronik | F8: ='Data Aset'!C10 | G8: ='Data Aset'!K10 | H8: ='Data Aset'!M10 | I8: ='Data Aset'!O10 | J8: 0 | K8: Garis Lurus | L8: =IFERROR(M8/12,"") | M8: =IFERROR((H8-J8)/I8,"") | N8: =IFERROR(M8,"") | O8: =IFERROR(H8-N8,"") | P8: Belum dihitung
A9: 8 | B9: Desember 2025 | C9: ='Data Aset'!B11 | D9: ='Data Aset'!F11 | E9: Elektronik | F9: ='Data Aset'!C11 | G9: ='Data Aset'!K11 | H9: ='Data Aset'!M11 | I9: ='Data Aset'!O11 | J9: 0 | K9: Garis Lurus | L9: =IFERROR(M9/12,"") | M9: =IFERROR((H9-J9)/I9,"") | N9: =IFERROR(M9,"") | O9: =IFERROR(H9-N9,"") | P9: Belum dihitung
A10: 9 | B10: Desember 2025 | C10: ='Data Aset'!B12 | D10: ='Data Aset'!F12 | E10: Elektronik | F10: ='Data Aset'!C12 | G10: ='Data Aset'!K12 | H10: ='Data Aset'!M12 | I10: ='Data Aset'!O12 | J10: 0 | K10: Garis Lurus | L10: =IFERROR(M10/12,"") | M10: =IFERROR((H10-J10)/I10,"") | N10: =IFERROR(M10,"") | O10: =IFERROR(H10-N10,"") | P10: Belum dihitung
A11: 10 | B11: Desember 2025 | C11: ='Data Aset'!B13 | D11: ='Data Aset'!F13 | E11: Elektronik | F11: ='Data Aset'!C13 | G11: ='Data Aset'!K13 | H11: ='Data Aset'!M13 | I11: ='Data Aset'!O13 | J11: 0 | K11: Garis Lurus | L11: =IFERROR(M11/12,"") | M11: =IFERROR((H11-J11)/I11,"") | N11: =IFERROR(M11,"") | O11: =IFERROR(H11-N11,"") | P11: Belum dihitung
A12: 11 | B12: Desember 2025 | C12: ='Data Aset'!B14 | D12: ='Data Aset'!F14 | E12: Elektronik | F12: ='Data Aset'!C14 | G12: ='Data Aset'!K14 | H12: ='Data Aset'!M14 | I12: ='Data Aset'!O14 | J12: 0 | K12: Garis Lurus | L12: =IFERROR(M12/12,"") | M12: =IFERROR((H12-J12)/I12,"") | N12: =IFERROR(M12,"") | O12: =IFERROR(H12-N12,"") | P12: Belum dihitung
A13: 12 | B13: Desember 2025 | C13: ='Data Aset'!B15 | D13: ='Data Aset'!F15 | E13: Elektronik | F13: ='Data Aset'!C15 | G13: ='Data Aset'!K15 | H13: ='Data Aset'!M15 | I13: ='Data Aset'!O15 | J13: 0 | K13: Garis Lurus | L13: =IFERROR(M13/12,"") | M13: =IFERROR((H13-J13)/I13,"") | N13: =IFERROR(M13,"") | O13: =IFERROR(H13-N13,"") | P13: Belum dihitung
... A104: 103 | B104: Desember 2025 | C104: ='Data Aset'!B106 | D104: ='Data Aset'!F106 | E104: Elektronik | F104: ='Data Aset'!C106 | G104: ='Data Aset'!K106 | H104: ='Data Aset'!M106 | I104: ='Data Aset'!O106 | J104: 0 | K104: Garis Lurus | L104: =IFERROR(M104/12,"") | M104: =IFERROR((H104-J104)/I104,"") | N104: =IFERROR(M104,"") | O104: =IFERROR(H104-N104,"") | P104: Belum dihitung

Sheet Jurnal Penyusutan
A1: No Jurnal | B1: Tanggal Jurnal | C1: Periode | D1: Kode Aset | E1: Nama Aset | F1: Kategori Aset | G1: Kode Akun Debit | H1: Nama Akun Debit | I1: Debit | J1: Kode Akun Kredit | K1: Nama Akun Kredit | L1: Kredit | M1: Keterangan
A2: =IF(Penyusutan!D2="","","JRN-"&TEXT(ROW()-1,"0000")) | B2: 46022 | C2: =Penyusutan!B2 | D2: =Penyusutan!C2 | E2: =Penyusutan!D2 | F2: Elektronik | H2: Beban Penyusutan Elektronik | I2: =Penyusutan!M2 | K2: Akumulasi Penyusutan Elektronik | L2: =Penyusutan!M2 | M2: =IF(E2="","","Penyusutan "&E2&" periode "&C2)
A3: =IF(Penyusutan!D3="","","JRN-"&TEXT(ROW()-1,"0000")) | B3: 46022 | C3: =Penyusutan!B3 | D3: =Penyusutan!C3 | E3: =Penyusutan!D3 | F3: Elektronik | H3: Beban Penyusutan Elektronik | I3: =Penyusutan!M3 | K3: Akumulasi Penyusutan Elektronik | L3: =Penyusutan!M3 | M3: =IF(E3="","","Penyusutan "&E3&" periode "&C3)
A4: =IF(Penyusutan!D4="","","JRN-"&TEXT(ROW()-1,"0000")) | B4: 46022 | C4: =Penyusutan!B4 | D4: =Penyusutan!C4 | E4: =Penyusutan!D4 | F4: Elektronik | H4: Beban Penyusutan Elektronik | I4: =Penyusutan!M4 | K4: Akumulasi Penyusutan Elektronik | L4: =Penyusutan!M4 | M4: =IF(E4="","","Penyusutan "&E4&" periode "&C4)
A5: =IF(Penyusutan!D5="","","JRN-"&TEXT(ROW()-1,"0000")) | B5: 46022 | C5: =Penyusutan!B5 | D5: =Penyusutan!C5 | E5: =Penyusutan!D5 | F5: Elektronik | H5: Beban Penyusutan Elektronik | I5: =Penyusutan!M5 | K5: Akumulasi Penyusutan Elektronik | L5: =Penyusutan!M5 | M5: =IF(E5="","","Penyusutan "&E5&" periode "&C5)
A6: =IF(Penyusutan!D6="","","JRN-"&TEXT(ROW()-1,"0000")) | B6: 46022 | C6: =Penyusutan!B6 | D6: =Penyusutan!C6 | E6: =Penyusutan!D6 | F6: Elektronik | H6: Beban Penyusutan Elektronik | I6: =Penyusutan!M6 | K6: Akumulasi Penyusutan Elektronik | L6: =Penyusutan!M6 | M6: =IF(E6="","","Penyusutan "&E6&" periode "&C6)
A7: =IF(Penyusutan!D7="","","JRN-"&TEXT(ROW()-1,"0000")) | B7: 46022 | C7: =Penyusutan!B7 | D7: =Penyusutan!C7 | E7: =Penyusutan!D7 | F7: Elektronik | H7: Beban Penyusutan Elektronik | I7: =Penyusutan!M7 | K7: Akumulasi Penyusutan Elektronik | L7: =Penyusutan!M7 | M7: =IF(E7="","","Penyusutan "&E7&" periode "&C7)
A8: =IF(Penyusutan!D8="","","JRN-"&TEXT(ROW()-1,"0000")) | B8: 46022 | C8: =Penyusutan!B8 | D8: =Penyusutan!C8 | E8: =Penyusutan!D8 | F8: Elektronik | H8: Beban Penyusutan Elektronik | I8: =Penyusutan!M8 | K8: Akumulasi Penyusutan Elektronik | L8: =Penyusutan!M8 | M8: =IF(E8="","","Penyusutan "&E8&" periode "&C8)
A9: =IF(Penyusutan!D9="","","JRN-"&TEXT(ROW()-1,"0000")) | B9: 46022 | C9: =Penyusutan!B9 | D9: =Penyusutan!C9 | E9: =Penyusutan!D9 | F9: Elektronik | H9: Beban Penyusutan Elektronik | I9: =Penyusutan!M9 | K9: Akumulasi Penyusutan Elektronik | L9: =Penyusutan!M9 | M9: =IF(E9="","","Penyusutan "&E9&" periode "&C9)
A10: =IF(Penyusutan!D10="","","JRN-"&TEXT(ROW()-1,"0000")) | B10: 46022 | C10: =Penyusutan!B10 | D10: =Penyusutan!C10 | E10: =Penyusutan!D10 | F10: Elektronik | H10: Beban Penyusutan Elektronik | I10: =Penyusutan!M10 | K10: Akumulasi Penyusutan Elektronik | L10: =Penyusutan!M10 | M10: =IF(E10="","","Penyusutan "&E10&" periode "&C10)
A11: =IF(Penyusutan!D11="","","JRN-"&TEXT(ROW()-1,"0000")) | B11: 46022 | C11: =Penyusutan!B11 | D11: =Penyusutan!C11 | E11: =Penyusutan!D11 | F11: Elektronik | H11: Beban Penyusutan Elektronik | I11: =Penyusutan!M11 | K11: Akumulasi Penyusutan Elektronik | L11: =Penyusutan!M11 | M11: =IF(E11="","","Penyusutan "&E11&" periode "&C11)
A12: =IF(Penyusutan!D12="","","JRN-"&TEXT(ROW()-1,"0000")) | B12: 46022 | C12: =Penyusutan!B12 | D12: =Penyusutan!C12 | E12: =Penyusutan!D12 | F12: Elektronik | H12: Beban Penyusutan Elektronik | I12: =Penyusutan!M12 | K12: Akumulasi Penyusutan Elektronik | L12: =Penyusutan!M12 | M12: =IF(E12="","","Penyusutan "&E12&" periode "&C12)
A13: =IF(Penyusutan!D13="","","JRN-"&TEXT(ROW()-1,"0000")) | B13: 46022 | C13: =Penyusutan!B13 | D13: =Penyusutan!C13 | E13: =Penyusutan!D13 | F13: Elektronik | H13: Beban Penyusutan Elektronik | I13: =Penyusutan!M13 | K13: Akumulasi Penyusutan Elektronik | L13: =Penyusutan!M13 | M13: =IF(E13="","","Penyusutan "&E13&" periode "&C13)
... A104: =IF(Penyusutan!D104="","","JRN-"&TEXT(ROW()-1,"0000")) | B104: 46022 | C104: =Penyusutan!B104 | D104: =Penyusutan!C104 | E104: =Penyusutan!D104 | F104: Elektronik | H104: Beban Penyusutan Elektronik | I104: =Penyusutan!M104 | K104: Akumulasi Penyusutan Elektronik | L104: =Penyusutan!M104 | M104: =IF(E104="","","Penyusutan "&E104&" periode "&C104)

Sheet Referensi
A1: Jenis Referensi | B1: Nilai
A2: Kondisi | B2: Baik
A3: Kondisi | B3: Kurang Baik
A4: Kondisi | B4: Rusak Ringan
A5: Kondisi | B5: Rusak Berat
A6: Kondisi | B6: Dalam Perbaikan
A7: Kondisi | B7: Hilang
A8: Status | B8: Aktif
A9: Status | B9: Tidak Aktif
A10: Status | B10: Dipindahkan
A11: Status | B11: Dihapuskan
A12: Status | B12: Dijual
... A14: Metode Penyusutan | B14: Saldo Menurun
